<?xml version="1.0" ?>
<!-- =================================================================================== -->
<!-- |    This document was autogenerated by xacro from ./wam7.urdf.xacro              | -->
<!-- |    EDITING THIS FILE BY HAND IS NOT RECOMMENDED                                 | -->
<!-- =================================================================================== -->
<robot name="wam">
  <!-- Include all the WAM stuff -->
  <material name="WAMGrey">
    <color rgba="0.7 0.7 0.7 1.0"/>
  </material>
  <material name="Red">
        <color rgba="0.8 0.0 0.0 1.0"/>
    </material>
    <material name="Blue">
        <color rgba="0.0 0.0 0.8 1.0"/>
    </material>
    <material name="White">
        <color rgba="1.0 1.0 1.0 1.0"/>
    </material>
    <material name="Black">
        <color rgba="0.0 0.0 0.0 1.0"/>
    </material>
  <!-- Root link is in the world frame-->
  <link name="world"/>
  <!-- 7-DOF Wam -->
  <joint name="wam/wam_fixed_joint" type="fixed">
    <parent link="world"/>
    <child link="wam/base_link"/>
    <origin xyz="0.0 0.0 0.0" rpy="0 0 0"/>
  </joint>
  <link name="wam/base_link">
    <inertial>
      <origin xyz="0 0 0"/>
      <mass value="1"/>
      <inertia ixx="0.1" ixy="0" ixz="0" iyy="0.1" iyz="0" izz="0.1"/>
    </inertial>
    <visual>
      <material name="WAMGrey">
        <color rgba="0.7 0.7 0.7 0.0"/>
      </material>
      <geometry>
        <mesh filename="package://sw_meshes/base_link_fine.stl"/>
      </geometry>
    </visual>
    <collision>
      <geometry>
        <mesh filename="package://sw_meshes/base_link_convex.dae"/>
      </geometry>
    </collision>
  </link>
  <joint name="wam/base_yaw_joint" type="revolute">
    <parent link="wam/base_link"/>
    <child link="wam/shoulder_yaw_link"/>
    <origin xyz="0 0 0.346" rpy="0 0 0"/>
    <axis xyz="0 0 1"/>
    <limit effort="60" lower="-2.6" upper="2.6" velocity="2.0"/>
    <dynamics damping="1.9800000000000002" friction="0"/>
  </joint>
  <link name="wam/shoulder_yaw_link">
    <inertial>
      <origin xyz="-.00443422 -.00066489 -0.1289039 "/>
      <mass value="5.0"/>
      <inertia ixx=".13488033" ixy="-0.00012485" ixz="0.00213041" iyy=".09046330" iyz="-.00068555" izz=".11328369"/>
    </inertial>
    <visual>
      <material name="WAMGrey">
        <color rgba="0.7 0.7 0.7 1.0"/>
      </material>
      <geometry>
        <mesh filename="package://sw_meshes/shoulder_link_fine.stl"/>
      </geometry>
    </visual>
    <collision>
      <geometry>
        <mesh filename="package://sw_meshes/shoulder_link_convex_decomposition.dae"/>
      </geometry>
    </collision>
  </link>
  <joint name="wam/shoulder_pitch_joint" type="revolute">
    <parent link="wam/shoulder_yaw_link"/>
    <child link="wam/shoulder_pitch_link"/>
    <origin xyz="0 0 0" rpy="-1.5707963267948966 0 0"/>
    <axis xyz="0 0 1"/>
    <limit effort="60" lower="-1.985" upper="1.985" velocity="2.0"/>
    <dynamics damping="0.55" friction="0"/>
  </joint>
  <link name="wam/shoulder_pitch_link">
    <visual>
      <material name="WAMGrey">
        <color rgba="0.7 0.7 0.7 1.0"/>
      </material>
      <geometry>
        <mesh filename="package://sw_meshes/shoulder_pitch_link_fine.stl"/>
      </geometry>
    </visual>
    
    <visual name="ball_2">
      <origin xyz="-0.0 -0.05 -0.0" rpy="0.0 -0.0 0.0"/>
      <geometry>
        <sphere radius="0.075"/>
      </geometry>
      <material name="Blue"/>
    </visual>
    <visual name="ball_2">
      <origin xyz="-0.0 -0.12 -0.0" rpy="0.0 -0.0 0.0"/>
      <geometry>
        <sphere radius="0.075"/>
      </geometry>
      <material name="Blue"/>
    </visual>
    <visual name="ball_2">
      <origin xyz="-0.0 -0.19 -0.0" rpy="0.0 -0.0 0.0"/>
      <geometry>
        <sphere radius="0.075"/>
      </geometry>
      <material name="Blue"/>
    </visual>
    <visual name="ball_2">
      <origin xyz="-0.0 -0.26 -0.0" rpy="0.0 -0.0 0.0"/>
      <geometry>
        <sphere radius="0.075"/>
      </geometry>
      <material name="Blue"/>
    </visual>
    <visual name="ball_2">
      <origin xyz="-0.0 -0.31 -0.0" rpy="0.0 -0.0 0.0"/>
      <geometry>
        <sphere radius="0.075"/>
      </geometry>
      <material name="Blue"/>
    </visual>
    <visual name="ball_2">
      <origin xyz="-0.0 -0.37 -0.0" rpy="0.0 -0.0 0.0"/>
      <geometry>
        <sphere radius="0.075"/>
      </geometry>
      <material name="Blue"/>
    </visual>
    <visual name="ball_2">
      <origin xyz="-0.0 -0.42 -0.0" rpy="0.0 -0.0 0.0"/>
      <geometry>
        <sphere radius="0.075"/>
      </geometry>
      <material name="Blue"/>
    </visual>
    <visual name="ball_2">
      <origin xyz="-0.0 -0.48 -0.0" rpy="0.0 -0.0 0.0"/>
      <geometry>
        <sphere radius="0.075"/>
      </geometry>
      <material name="Blue"/>
    </visual>
    <visual name="ball_0">
      <origin xyz="0.0 -0.54 0.0" rpy="0.0 -0.0 0.0"/>
      <geometry>
        <sphere radius="0.1"/>
      </geometry>
      <material name="Blue"/>
    </visual>
    <inertial>
      <origin xyz="-.00236981 -.01542114 .03105614 "/>
      <mass value="3.87493756"/>
      <inertia ixx="0.02140958" ixy="-0.00002461" ixz="0.00027172" iyy="0.015589060" iyz="0.0018192" izz="0.01377875"/>
    </inertial>
    <collision>
      <geometry>
        <mesh filename="package://sw_meshes/shoulder_pitch_link_convex.dae"/>
      </geometry>
    </collision>
  </link>
  <joint name="wam/shoulder_yaw_joint" type="revolute">
    <parent link="wam/shoulder_pitch_link"/>
    <child link="wam/upper_arm_link"/>
    <origin xyz="0 0 0" rpy="1.5707963267948966 0 0"/>
    <axis xyz="0 0 1"/>
    <limit effort="45" lower="-2.8" upper="2.8" velocity="2.0"/>
    <dynamics damping="1.6500000000000001" friction="0"/>
  </joint>
  <link name="wam/upper_arm_link">
    <inertial>
      <origin xyz="0.00683258580000000 0.000033090000000 0.392492300000000"/>
      <mass value="2.20228141"/>
      <inertia ixx=".05911077" ixy="-0.00000738" ixz="-0.00249612" iyy="0.05927043" iyz="0.00001767" izz="0.0032455"/>
    </inertial>
    <visual>
      <material name="WAMGrey">
        <color rgba="0.7 0.7 0.7 1.0"/>
      </material>
      <geometry>
        <mesh filename="package://sw_meshes/upper_arm_link_fine.stl"/>
      </geometry>
    </visual>
    <collision>
      <geometry>
        <mesh filename="package://sw_meshes/upper_arm_link_convex_decomposition.dae"/>
      </geometry>
    </collision>
  </link>
  <joint name="wam/elbow_pitch_joint" type="revolute">
    <parent link="wam/upper_arm_link"/>
    <child link="wam/forearm_link"/>
    <origin xyz="0.045 0 0.55" rpy="-1.5707963267948966 0 0"/>
    <axis xyz="0 0 1"/>
    <limit effort="30" lower="-0.9" upper="3.141592653589793" velocity="2.00"/>
    <dynamics damping="0.8800000000000001" friction="0"/>
  </joint>
  <link name="wam/forearm_link">
    <inertial>
      <mass value="0.50016804"/>
      <origin xyz="-0.04001488 -.14271662 -.00022942 " rpy="0 0 0"/>
      <inertia ixx="0.01491672" ixy="0.001506040000000" ixz="0.000017410000000" iyy="0.002944630000000" iyz="0.000021090000000" izz="0.014829880000000"/>
    </inertial>
    <visual>
      <geometry>
        <mesh filename="package://sw_meshes/elbow_link_fine.stl"/>
      </geometry>
    </visual>
    <visual name="ball_0">
      <origin xyz="-0.045 -0.05 0.0" rpy="0.0 -0.0 0.0"/>
      <geometry>
        <sphere radius="0.0675"/>
      </geometry>
      <material name="WAMGrey"/>
    </visual>
    <visual name="ball_0">
      <origin xyz="-0.045 -0.12 0.0" rpy="0.0 -0.0 0.0"/>
      <geometry>
        <sphere radius="0.0675"/>
      </geometry>
      <material name="WAMGrey"/>
    </visual>
    <visual name="ball_0">
      <origin xyz="-0.045 -0.2 0.0" rpy="0.0 -0.0 0.0"/>
      <geometry>
        <sphere radius="0.065"/>
      </geometry>
      <material name="WAMGrey"/>
    </visual>
    <visual name="ball_0">
      <origin xyz="-0.045 -0.25 0.0" rpy="0.0 -0.0 0.0"/>
      <geometry>
        <sphere radius="0.065"/>
      </geometry>
      <material name="WAMGrey"/>
    </visual>
    <collision>
      <geometry>
        <mesh filename="package://sw_meshes/elbow_link_convex.dae"/>
      </geometry>
    </collision>
    <visual>
      <origin xyz="-0.045 -0.0730 0" rpy="1.5707963267948966 0 0"/>
      <geometry>
        <mesh filename="package://sw_meshes/forearm_link_fine.stl"/>
      </geometry>
    </visual>
    <collision>
      <origin xyz="-0.045 -0.0730 0" rpy="1.5707963267948966 0 0"/>
      <geometry>
        <mesh filename="package://sw_meshes/forearm_link_convex_decomposition.dae"/>
      </geometry>
    </collision>
  </link>
  <joint name="wam/wrist_yaw_joint" type="revolute">
    <parent link="wam/forearm_link"/>
    <child link="wam/wrist_yaw_link"/>
    <origin xyz="-0.045 -0.3 0" rpy="1.5707963267948966 0 0"/>
    <axis xyz="0 0 1"/>
    <limit effort="10" lower="-4.55" upper="1.25" velocity="2.0"/>
    <dynamics damping="0.55" friction="0"/>
  </joint>
  <link name="wam/wrist_yaw_link">
    <inertial>
      <origin xyz="0.00008921 0.00435824 -0.00511217 "/>
      <mass value="1.05376019"/>
      <inertia ixx="0.00005029" ixy="0.00000020" ixz="0.00007582" iyy="0.00007582" iyz="-0.00000359" izz="0.00006270"/>
    </inertial>
    <visual>
      <material name="WAMGrey">
        <color rgba="0.7 0.7 0.7 1.0"/>
      </material>
      <origin xyz="0 0 0" rpy="0 0 0"/>
      <geometry>
        <mesh filename="package://sw_meshes/wrist_yaw_link_fine.stl"/>
      </geometry>
    </visual>
    
    <collision>
      <origin xyz="0 0 0" rpy="0 0 0"/>
      <geometry>
        <mesh filename="package://sw_meshes/wrist_yaw_link_convex_decomposition.dae"/>
      </geometry>
    </collision>
  </link>
  <joint name="wam/wrist_pitch_joint" type="revolute">
    <parent link="wam/wrist_yaw_link"/>
    <child link="wam/wrist_pitch_link"/>
    <origin xyz="0 0 0" rpy="-1.5707963267948966 0 0"/>
    <axis xyz="0 0 1"/>
    <limit effort="10" lower="-1.5707" upper="1.5707" velocity="2.00"/>
    <dynamics damping="0.11000000000000001" friction="0"/>
  </joint>
  <link name="wam/wrist_pitch_link">
    <inertial>
      <origin xyz="-0.00012262 -0.02468336 -0.01703194 " rpy="0 0 0"/>
      <mass value="0.51797364"/>
      <inertia ixx="0.00055516" ixy="0.00000061" ixz="-0.00000074" iyy="0.00024367" iyz="-0.00004590" izz="0.00045358"/>
    </inertial>
    <visual>
      <material name="WAMGrey">
        <color rgba="0.7 0.7 0.7 1.0"/>
      </material>
      <geometry>
        <mesh filename="package://sw_meshes/wrist_pitch_link_fine.stl"/>
      </geometry>
    </visual>
    <visual name="ball_0">
      <origin xyz="0.0 -0.0 0.0" rpy="0.0 -0.0 0.0"/>
      <geometry>
        <sphere radius="0.0675"/>
      </geometry>
      <material name="Blue"/>
    </visual>
    <collision>
      <geometry>
        <mesh filename="package://sw_meshes/wrist_pitch_link_convex_decomposition.dae"/>
      </geometry>
    </collision>
  </link>
  <joint name="wam/palm_yaw_joint" type="revolute">
    <parent link="wam/wrist_pitch_link"/>
    <child link="wam/wrist_palm_link"/>
    <origin xyz="0 0 0" rpy="1.5707963267948966 0 0"/>
    <axis xyz="0 0 1"/>
    <limit effort="10" lower="-3.0" upper="3.0" velocity="2.00"/>
    <!-- 2.95 is a limit taken in from 3 due to safety and differences between arms. -->
    <dynamics damping="0.11000000000000001" friction="0"/>
  </joint>
  <link name="wam/wrist_palm_link">
    <inertial>
      <origin xyz="0.0 0.0 0.055" rpy="0 0 0"/>
      <mass value="0.08286134"/>
      <inertia ixx="0.00010859" ixy="0.00000000" ixz="-0.00000000" iyy="0.00020683" iyz="-0.0000000" izz="0.00010851"/>
    </inertial>
    <visual>
      <material name="WAMGrey">
        <color rgba="0.7 0.7 0.7 1.0"/>
      </material>
      <origin xyz="0 0 0" rpy="0 0 0"/>
      <geometry>
        <mesh filename="package://sw_meshes/wrist_palm_link_fine.stl"/>
      </geometry>
    </visual>
    
    <collision>
      <origin xyz="0 0 0" rpy="0 0 0"/>
      <geometry>
        <mesh filename="package://sw_meshes/wrist_palm_link_convex.dae"/>
      </geometry>
    </collision>
  </link>
  <joint name="wam/wrist_palm_stump_joint" type="fixed">
    <parent link="wam/wrist_palm_link"/>
    <child link="wam/wrist_palm_stump_link"/>
    <origin xyz="0 0 0.06" rpy="0 0 0"/>
  </joint>
  <link name="wam/wrist_palm_stump_link">
    <inertial>
      <mass value="0.000001"/>
      <inertia ixx="0.0000001" ixy="0.0" ixz="0.0" iyy="0.0000001" iyz="0.0" izz="0.0000001"/>
    </inertial>

    <visual name="ball_0">
      <origin xyz="0.0 -0.0 0.0" rpy="0.0 -0.0 0.0"/>
      <geometry>
        <sphere radius="0.0575"/>
      </geometry>
      <material name="Red"/>
    </visual>
    <visual name="ball_0">
      <origin xyz="0.0 -0.0 0.05" rpy="0.0 -0.0 0.0"/>
      <geometry>
        <sphere radius="0.0575"/>
      </geometry>
      <material name="Red"/>
    </visual>
    <visual name="ball_0">
      <origin xyz="0.0 0.07 0.08" rpy="0.0 -0.0 0.0"/>
      <geometry>
        <sphere radius="0.034"/>
      </geometry>
      <material name="Red"/>
    </visual>
    <visual name="ball_0">
      <origin xyz="0.0 0.11 0.08" rpy="0.0 -0.0 0.0"/>
      <geometry>
        <sphere radius="0.034"/>
      </geometry>
      <material name="Red"/>
    </visual>
    <visual name="ball_0">
      <origin xyz="0.0 0.15 0.1" rpy="0.0 -0.0 0.0"/>
      <geometry>
        <sphere radius="0.034"/>
      </geometry>
      <material name="Red"/>
    </visual>

    <visual name="ball_0">
      <origin xyz="-0.025 -0.07 0.08" rpy="0.0 -0.0 0.0"/>
      <geometry>
        <sphere radius="0.034"/>
      </geometry>
      <material name="Red"/>
    </visual>
    <visual name="ball_0">
      <origin xyz="-0.025 -0.11 0.08" rpy="0.0 -0.0 0.0"/>
      <geometry>
        <sphere radius="0.034"/>
      </geometry>
      <material name="Red"/>
    </visual>
    <visual name="ball_0">
      <origin xyz="-0.025 -0.15 0.1" rpy="0.0 -0.0 0.0"/>
      <geometry>
        <sphere radius="0.034"/>
      </geometry>
      <material name="Red"/>
    </visual>

    <visual name="ball_0">
      <origin xyz="0.025 -0.07 0.08" rpy="0.0 -0.0 0.0"/>
      <geometry>
        <sphere radius="0.034"/>
      </geometry>
      <material name="Red"/>
    </visual>
    <visual name="ball_0">
      <origin xyz="0.025 -0.11 0.08" rpy="0.0 -0.0 0.0"/>
      <geometry>
        <sphere radius="0.034"/>
      </geometry>
      <material name="Red"/>
    </visual>
    <visual name="ball_0">
      <origin xyz="0.025 -0.15 0.1" rpy="0.0 -0.0 0.0"/>
      <geometry>
        <sphere radius="0.034"/>
      </geometry>
      <material name="Red"/>
    </visual>
  </link>
  <!-- BHand -->
  <joint name="wam/bhand/bhand_base_joint" type="fixed">
    <parent link="wam/wrist_palm_link"/>
    <child link="wam/bhand/bhand_palm_link"/>
    <origin xyz="0 0 0.06" rpy="0 0 0"/>
  </joint>
  <link name="wam/bhand/bhand_palm_link">
    <inertial>
      <origin xyz="-5.1098e-005 0.0050433 0.036671"/>
      <mass value="0.50573"/>
      <inertia ixx="3.8374e-005" ixy="-5.604e-008" ixz="-4.2034e-005" iyy="0.00022405" iyz="1.3283e-007" izz="0.00020045"/>
    </inertial>
    <visual>
      <geometry>
        <mesh filename="package://sw_meshes/bhand/bhand_palm_fine.stl"/>
      </geometry>
      <material name="Red"/>
    </visual>
    <collision>
      <geometry>
        <mesh filename="package://sw_meshes/bhand/bhand_palm_link_convex_decomposition.dae"/>
      </geometry>
    </collision>
  </link>
  <joint name="wam/bhand/bhand_palm_surface_joint" type="fixed">
    <parent link="wam/bhand/bhand_palm_link"/>
    <child link="wam/bhand/bhand_palm_surface_link"/>
    <origin xyz="0 0 0.08" rpy="0 0 0"/>
    <limit effort="5" lower="0" upper="3.141592653589793" velocity="5.0"/>
    <dynamics damping="0.11000000000000001" friction="0"/>
  </joint>
  <link name="wam/bhand/bhand_palm_surface_link">
    <inertial>
      <mass value="0.000001"/>
      <inertia ixx="0.000001" ixy="0.0" ixz="0.0" iyy="0.000001" iyz="0.0" izz="0.000001"/>
    </inertial>
  </link>
  <joint name="wam/bhand/bhand_grasp_joint" type="fixed">
    <parent link="wam/bhand/bhand_palm_link"/>
    <child link="wam/bhand/bhand_grasp_link"/>
    <origin xyz="0 0 0.12" rpy="0 0 0"/>
    <limit effort="5" lower="0" upper="3.141592653589793" velocity="5.0"/>
    <dynamics damping="0.11000000000000001" friction="0"/>
  </joint>
  <link name="wam/bhand/bhand_grasp_link">
    <inertial>
      <mass value="0.000001"/>
      <inertia ixx="0.000001" ixy="0.0" ixz="0.0" iyy="0.000001" iyz="0.0" izz="0.000001"/>
    </inertial>
  </link>
  <joint name="wam/bhand/finger_1/prox_joint" type="revolute">
    <parent link="wam/bhand/bhand_palm_link"/>
    <child link="wam/bhand/finger_1/prox_link"/>
    <origin xyz="-0.025 0.0 0.0415" rpy="0 0 -1.5707963267948966"/>
    <axis xyz="0 0 -1"/>
    <limit effort="5" lower="0" upper="3.141592653589793" velocity="5.0"/>
    <dynamics damping="0.11000000000000001" friction="0"/>
  </joint>
  <link name="wam/bhand/finger_1/prox_link">
    <inertial>
      <origin xyz="0.023133 0.00078642 0.00052792"/>
      <mass value="0.14109"/>
      <inertia ixx="4.872e-006" ixy="1.7103e-006" ixz="3.4041e-008" iyy="7.6588e-005" iyz="2.3133e-008" izz="7.7733e-005"/>
    </inertial>
    <visual>
      <material name="WAMGrey"/>
      <geometry>
        <mesh filename="package://sw_meshes/bhand/bhand_finger_prox_link_fine.stl"/>
      </geometry>
    </visual>
    <collision>
      <geometry>
        <mesh filename="package://sw_meshes/bhand/bhand_finger_prox_link_convex_decomposition.dae"/>
      </geometry>
    </collision>
  </link>
  <joint name="wam/bhand/finger_1/med_joint" type="revolute">
    <parent link="wam/bhand/finger_1/prox_link"/>
    <child link="wam/bhand/finger_1/med_link"/>
    <origin xyz="0.05 0.0 0.03390" rpy="1.5707963267948966 0 0"/>
    <axis xyz="0 0 1"/>
    <limit effort="5" lower="0" upper="2.443460952792061" velocity="5.00"/>
    <dynamics damping="0.11000000000000001" friction="0"/>
  </joint>
  <link name="wam/bhand/finger_1/med_link">
    <inertial>
      <origin xyz="0.023133 0.00078642 0.00052792"/>
      <mass value="0.062139"/>
      <inertia ixx="4.872e-006" ixy="1.7103e-006" ixz="3.4041e-008" iyy="7.6588e-005" iyz="2.3133e-008" izz="7.7733e-005"/>
    </inertial>
    <visual>
      <material name="WAMGrey"/>
      <geometry>
        <mesh filename="package://sw_meshes/bhand/bhand_finger_med_link_fine.stl"/>
      </geometry>
    </visual>
    <collision>
      <geometry>
        <mesh filename="package://sw_meshes/bhand/bhand_finger_med_link_convex.dae"/>
      </geometry>
    </collision>
  </link>
  <joint name="wam/bhand/finger_1/dist_joint" type="revolute">
    <parent link="wam/bhand/finger_1/med_link"/>
    <child link="wam/bhand/finger_1/dist_link"/>
    <origin xyz="0.06994 0.003 0.0" rpy="0 0 0.7853981633974483"/>
    <axis xyz="0 0 1"/>
    <limit effort="5" lower="0" upper="0.8377580409572781" velocity="5.00"/>
    <dynamics damping="0.11000000000000001" friction="0"/>
  </joint>
  <link name="wam/bhand/finger_1/dist_link">
    <inertial>
      <origin xyz="0.022825 0.0010491 0.0004203" rpy="0 0 0"/>
      <mass value="0.041377"/>
      <inertia ixx="3.1582e-006" ixy="1.4308e-006" ixz="1.0106e-007" iyy="3.8376e-005" iyz="0" izz="3.7275e-005"/>
    </inertial>
    <visual>
      <origin rpy="0 0 -0.7853981633974483"/>
      <material name="WAMGrey"/>
      <geometry>
        <mesh filename="package://sw_meshes/bhand/bhand_finger_dist_link_fine.stl"/>
      </geometry>
    </visual>
    <collision>
      <origin rpy="0 0 -0.7853981633974483"/>
      <geometry>
        <mesh filename="package://sw_meshes/bhand/bhand_finger_dist_link_convex.dae"/>
      </geometry>
    </collision>
  </link>
  <joint name="wam/bhand/finger_1/tip_joint" type="fixed">
    <parent link="wam/bhand/finger_1/dist_link"/>
    <child link="wam/bhand/finger_1/tip_link"/>
    <origin xyz="0.05 0.0 0.0" rpy="0 0 0"/>
  </joint>
  <link name="wam/bhand/finger_1/tip_link">
    <inertial>
      <mass value="1E-6"/>
      <inertia ixx="1E-6" ixy="0" ixz="0" iyy="1E-6" iyz="0" izz="1E-6"/>
    </inertial>
  </link>
  <joint name="wam/bhand/finger_2/prox_joint" type="revolute">
    <parent link="wam/bhand/bhand_palm_link"/>
    <child link="wam/bhand/finger_2/prox_link"/>
    <origin xyz="0.025 0.0 0.0415" rpy="0 0 -1.5707963267948966"/>
    <axis xyz="0 0 1"/>
    <limit effort="5" lower="0" upper="3.141592653589793" velocity="5.0"/>
    <dynamics damping="0.11000000000000001" friction="0"/>
  </joint>
  <link name="wam/bhand/finger_2/prox_link">
    <inertial>
      <origin xyz="0.023133 0.00078642 0.00052792"/>
      <mass value="0.14109"/>
      <inertia ixx="4.872e-006" ixy="1.7103e-006" ixz="3.4041e-008" iyy="7.6588e-005" iyz="2.3133e-008" izz="7.7733e-005"/>
    </inertial>
    <visual>
      <material name="WAMGrey"/>
      <geometry>
        <mesh filename="package://sw_meshes/bhand/bhand_finger_prox_link_fine.stl"/>
      </geometry>
    </visual>
    <collision>
      <geometry>
        <mesh filename="package://sw_meshes/bhand/bhand_finger_prox_link_convex_decomposition.dae"/>
      </geometry>
    </collision>
  </link>
  <joint name="wam/bhand/finger_2/med_joint" type="revolute">
    <parent link="wam/bhand/finger_2/prox_link"/>
    <child link="wam/bhand/finger_2/med_link"/>
    <origin xyz="0.05 0.0 0.03390" rpy="1.5707963267948966 0 0"/>
    <axis xyz="0 0 1"/>
    <limit effort="5" lower="0" upper="2.443460952792061" velocity="5.00"/>
    <dynamics damping="0.11000000000000001" friction="0"/>
  </joint>
  <link name="wam/bhand/finger_2/med_link">
    <inertial>
      <origin xyz="0.023133 0.00078642 0.00052792"/>
      <mass value="0.062139"/>
      <inertia ixx="4.872e-006" ixy="1.7103e-006" ixz="3.4041e-008" iyy="7.6588e-005" iyz="2.3133e-008" izz="7.7733e-005"/>
    </inertial>
    <visual>
      <material name="WAMGrey"/>
      <geometry>
        <mesh filename="package://sw_meshes/bhand/bhand_finger_med_link_fine.stl"/>
      </geometry>
    </visual>
    <collision>
      <geometry>
        <mesh filename="package://sw_meshes/bhand/bhand_finger_med_link_convex.dae"/>
      </geometry>
    </collision>
  </link>
  <joint name="wam/bhand/finger_2/dist_joint" type="revolute">
    <parent link="wam/bhand/finger_2/med_link"/>
    <child link="wam/bhand/finger_2/dist_link"/>
    <origin xyz="0.06994 0.003 0.0" rpy="0 0 0.7853981633974483"/>
    <axis xyz="0 0 1"/>
    <limit effort="5" lower="0" upper="0.8377580409572781" velocity="5.00"/>
    <dynamics damping="0.11000000000000001" friction="0"/>
  </joint>
  <link name="wam/bhand/finger_2/dist_link">
    <inertial>
      <origin xyz="0.022825 0.0010491 0.0004203" rpy="0 0 0"/>
      <mass value="0.041377"/>
      <inertia ixx="3.1582e-006" ixy="1.4308e-006" ixz="1.0106e-007" iyy="3.8376e-005" iyz="0" izz="3.7275e-005"/>
    </inertial>
    <visual>
      <origin rpy="0 0 -0.7853981633974483"/>
      <material name="WAMGrey"/>
      <geometry>
        <mesh filename="package://sw_meshes/bhand/bhand_finger_dist_link_fine.stl"/>
      </geometry>
    </visual>
    <collision>
      <origin rpy="0 0 -0.7853981633974483"/>
      <geometry>
        <mesh filename="package://sw_meshes/bhand/bhand_finger_dist_link_convex.dae"/>
      </geometry>
    </collision>
  </link>
  <joint name="wam/bhand/finger_2/tip_joint" type="fixed">
    <parent link="wam/bhand/finger_2/dist_link"/>
    <child link="wam/bhand/finger_2/tip_link"/>
    <origin xyz="0.05 0.0 0.0" rpy="0 0 0"/>
  </joint>
  <link name="wam/bhand/finger_2/tip_link">
    <inertial>
      <mass value="1E-6"/>
      <inertia ixx="1E-6" ixy="0" ixz="0" iyy="1E-6" iyz="0" izz="1E-6"/>
    </inertial>
  </link>
  <joint name="wam/bhand/finger_3/med_joint" type="revolute">
    <parent link="wam/bhand/bhand_palm_link"/>
    <child link="wam/bhand/finger_3/med_link"/>
    <origin xyz="0 0.05 0.0754" rpy="1.5707963267948966 0 1.5707963267948966"/>
    <axis xyz="0 0 1"/>
    <limit effort="5" lower="0" upper="2.443460952792061" velocity="5.00"/>
    <dynamics damping="0.11000000000000001" friction="0"/>
  </joint>
  <link name="wam/bhand/finger_3/med_link">
    <inertial>
      <origin xyz="0.023133 0.00078642 0.00052792"/>
      <mass value="0.062139"/>
      <inertia ixx="4.872e-006" ixy="1.7103e-006" ixz="3.4041e-008" iyy="7.6588e-005" iyz="2.3133e-008" izz="7.7733e-005"/>
    </inertial>
    <visual>
      <material name="WAMGrey"/>
      <geometry>
        <mesh filename="package://sw_meshes/bhand/bhand_finger_med_link_fine.stl"/>
      </geometry>
    </visual>
    <collision>
      <geometry>
        <mesh filename="package://sw_meshes/bhand/bhand_finger_med_link_convex.dae"/>
      </geometry>
    </collision>
  </link>
  <joint name="wam/bhand/finger_3/dist_joint" type="revolute">
    <parent link="wam/bhand/finger_3/med_link"/>
    <child link="wam/bhand/finger_3/dist_link"/>
    <origin xyz="0.06994 0.003 0.0" rpy="0 0 0.7853981633974483"/>
    <axis xyz="0 0 1"/>
    <limit effort="5" lower="0" upper="0.8377580409572781" velocity="5.00"/>
    <dynamics damping="0.11000000000000001" friction="0"/>
  </joint>
  <link name="wam/bhand/finger_3/dist_link">
    <inertial>
      <origin xyz="0.022825 0.0010491 0.0004203" rpy="0 0 0"/>
      <mass value="0.041377"/>
      <inertia ixx="3.1582e-006" ixy="1.4308e-006" ixz="1.0106e-007" iyy="3.8376e-005" iyz="0" izz="3.7275e-005"/>
    </inertial>
    <visual>
      <origin rpy="0 0 -0.7853981633974483"/>
      <material name="WAMGrey"/>
      <geometry>
        <mesh filename="package://sw_meshes/bhand/bhand_finger_dist_link_fine.stl"/>
      </geometry>
    </visual>
    <collision>
      <origin rpy="0 0 -0.7853981633974483"/>
      <geometry>
        <mesh filename="package://sw_meshes/bhand/bhand_finger_dist_link_convex.dae"/>
      </geometry>
    </collision>
  </link>
  <joint name="wam/bhand/finger_3/tip_joint" type="fixed">
    <parent link="wam/bhand/finger_3/dist_link"/>
    <child link="wam/bhand/finger_3/tip_link"/>
    <origin xyz="0.05 0.0 0.0" rpy="0 0 0"/>
  </joint>
  <link name="wam/bhand/finger_3/tip_link">
    <inertial>
      <mass value="1E-6"/>
      <inertia ixx="1E-6" ixy="0" ixz="0" iyy="1E-6" iyz="0" izz="1E-6"/>
    </inertial>
  </link>
</robot>