<?xml version="1.0" ?>

<robot name="spheres">

    <joint name="r_shoulder_pan_joint" type="revolute">
        <axis xyz="0 0 1"/>
        <origin rpy="0 0 0" xyz="0.0 -0.188 0.0"/>
        <parent link="torso_lift_link"/>
        <child link="r_shoulder_pan_link"/>
        <limit effort="30" lower="-2.2853981634" upper="0.714601836603" velocity="2.088"/>
        <!-- alpha tested velocity and effort limits -->
        <dynamics damping="10.0"/>
        <safety_controller k_position="100" k_velocity="10" soft_lower_limit="-2.1353981634"
                           soft_upper_limit="0.564601836603"/>
        <!-- joint angle when the rising or the falling flag is activated on PR2 -->
        <calibration rising="-0.785398163397"/>
    </joint>

    <joint name="r_shoulder_lift_joint" type="revolute">
        <axis xyz="0 1 0"/>
        <origin rpy="0 0 0" xyz="0.1 0 0"/>
        <limit effort="30" lower="-0.5236" upper="1.3963" velocity="2.082"/>
        <!-- alpha tested velocity and effort limits -->
        <safety_controller k_position="100" k_velocity="10" soft_lower_limit="-0.3536" soft_upper_limit="1.2963"/>
        <calibration falling="0.0"/>
        <dynamics damping="10.0"/>
        <parent link="r_shoulder_pan_link"/>
        <child link="r_shoulder_lift_link"/>
    </joint>

    <joint name="r_upper_arm_roll_joint" type="revolute">
        <axis xyz="1 0 0"/>
        <origin rpy="0 0 0" xyz="0 0 0"/>
        <limit effort="30" lower="-0.5236" upper="1.3963" velocity="2.082"/>
        <safety_controller k_position="100" k_velocity="10" soft_lower_limit="-0.3536" soft_upper_limit="1.2963"/>
        <calibration rising="-1.57079632679"/>
        <dynamics damping="0.1"/>
        <parent link="r_shoulder_lift_link"/>
        <child link="r_upper_arm_roll_link"/>
    </joint>

    <joint name="r_upper_arm_joint" type="fixed">
        <origin rpy="0 0 0" xyz="0 0 0"/>
        <parent link="r_upper_arm_roll_link"/>
        <child link="r_upper_arm_link"/>
    </joint>

    <joint name="r_elbow_flex_joint" type="revolute">
        <axis xyz="0 1 0"/>
        <origin rpy="0 0 0" xyz="0.4 0 0"/>
        <limit effort="30" lower="-2.3213" upper="0.00" velocity="3.3"/>
        <safety_controller k_position="100" k_velocity="3" soft_lower_limit="-2.1213" soft_upper_limit="-0.15"/>
        <calibration falling="-1.1606"/>
        <parent link="r_upper_arm_link"/>
        <child link="r_elbow_flex_link"/>
    </joint>

    <joint name="r_forearm_joint" type="fixed">
        <origin rpy="0 0 0" xyz="0 0 0"/>
        <!-- transform from parent link to this joint frame -->
        <parent link="r_forearm_roll_link"/>
        <child link="r_forearm_link"/>
    </joint>

    <joint name="r_forearm_roll_joint" type="continuous">
        <axis xyz="1 0 0"/>
        <origin rpy="0 0 0" xyz="0 0 0"/>
        <limit effort="30" velocity="3.6"/>
        <!-- alpha tested velocity and effort limits -->
        <safety_controller k_velocity="1"/>
        <calibration rising="0.0"/>
        <dynamics damping="0.1"/>
        <parent link="r_elbow_flex_link"/>
        <child link="r_forearm_roll_link"/>
    </joint>

    <joint name="r_wrist_flex_joint" type="revolute">
        <axis xyz="0 1 0"/>
        <limit effort="10" lower="-2.18" upper="0.0" velocity="3.078"/>
        <!-- alpha tested velocity and effort limits -->
        <safety_controller k_position="20" k_velocity="4" soft_lower_limit="-2.0" soft_upper_limit="-0.1"/>
        <dynamics damping="0.1"/>
        <calibration falling="-0.5410521"/>
        <origin rpy="0 0 0" xyz="0.321 0 0"/>
        <parent link="r_forearm_link"/>
        <child link="r_wrist_flex_link"/>
    </joint>

    <joint name="r_wrist_roll_joint" type="continuous">
        <axis xyz="1 0 0"/>
        <limit effort="10" velocity="3.6"/>
        <!-- alpha tested velocity and effort limits -->
        <safety_controller k_velocity="2"/>
        <dynamics damping="0.1"/>
        <calibration rising="-1.57079632679"/>
        <origin rpy="0 0 0" xyz="0 0 0"/>
        <parent link="r_wrist_flex_link"/>
        <child link="r_wrist_roll_link"/>
    </joint>

    <joint name="r_gripper_palm_joint" type="fixed">
        <origin rpy="0 0 0" xyz="0 0 0"/>
        <parent link="r_wrist_roll_link"/>
        <child link="r_gripper_palm_link"/>
    </joint>

    <!-- pr2 fingers macro -->
    <!-- Finger proximal digit -->
    <joint name="r_gripper_l_finger_joint" type="revolute">
        <axis xyz="0 0 1"/>
        <!-- limits on passive finger and finger top joints without
             transmission are not enforced by safety controllers.
             The lower/upper limits and are enforced in PR2 simulation and
             effort and velocity limits are ignored. This is also needed because
             these joints are declared revolute rather than continuous.-->
        <limit effort="1000.0" lower="0.0" upper="0.548" velocity="0.5"/>
        <dynamics damping="0.02"/>
        <origin rpy="0 0 0" xyz="0.07691 0.01 0"/>
        <parent link="r_gripper_palm_link"/>
        <child link="r_gripper_l_finger_link"/>
    </joint>

    <joint name="r_gripper_r_finger_joint" type="revolute">
        <axis xyz="0 0 -1"/>
        <origin rpy="0 0 0" xyz="0.07691 -0.01 0"/>
        <!-- limits on passive finger and finger top joints without
             transmission are not enforced by safety controllers.
             The lower/upper limits and are enforced in PR2 simulation and
             effort and velocity limits are ignored. This is also needed because
             these joints are declared revolute rather than continuous.-->
        <limit effort="1000.0" lower="0.0" upper="0.548" velocity="0.5"/>
        <dynamics damping="0.02"/>
        <mimic joint="r_gripper_l_finger_joint" multiplier="1" offset="0"/>
        <parent link="r_gripper_palm_link"/>
        <child link="r_gripper_r_finger_link"/>
    </joint>

    <!-- Finger tip -->
    <joint name="r_gripper_l_finger_tip_joint" type="revolute">
        <axis xyz="0 0 -1"/>
        <origin rpy="0 0 0" xyz="0.09137 0.00495 0"/>
        <!-- limits on passive finger and finger top joints without
             transmission are not enforced by safety controllers.
             The lower/upper limits and are enforced in PR2 simulation and
             effort and velocity limits are ignored. This is also needed because
             these joints are declared revolute rather than continuous.-->
        <limit effort="1000.0" lower="0.0" upper="0.548" velocity="0.5"/>
        <dynamics damping="0.001"/>
        <mimic joint="r_gripper_l_finger_joint" multiplier="1" offset="0"/>
        <parent link="r_gripper_l_finger_link"/>
        <child link="r_gripper_l_finger_tip_link"/>
    </joint>


    <joint name="r_gripper_r_finger_tip_joint" type="revolute">
        <axis xyz="0 0 1"/>
        <origin rpy="0 0 0" xyz="0.09137 -0.00495 0"/>
        <!-- limits on passive finger and finger top joints without
             transmission are not enforced by safety controllers.
             The lower/upper limits and are enforced in PR2 simulation and
             effort and velocity limits are ignored. This is also needed because
             these joints are declared revolute rather than continuous.-->
        <limit effort="1000.0" lower="0.0" upper="0.548" velocity="0.5"/>
        <dynamics damping="0.001"/>
        <mimic joint="r_gripper_l_finger_joint" multiplier="1" offset="0"/>
        <parent link="r_gripper_r_finger_link"/>
        <child link="r_gripper_r_finger_tip_link"/>
    </joint>

    <link name="r_gripper_palm_link">
        <inertial>
            <mass value="0.58007"/>
            <origin rpy="0 0 0" xyz="0.06623 0.00053 -0.00119"/>
            <inertia ixx="0.00035223921" ixy="-0.00001580476" ixz="-0.00000091750" iyy="0.00067741312"
                     iyz="-0.00000059554" izz="0.00086563316"/>
        </inertial>
        <visual>
            <origin rpy="0 0 0" xyz="0 0 0"/>
            <geometry>
                <mesh filename="meshes/gripper_v0/gripper_palm.dae"/>
            </geometry>
            <material name="Red"/>
        </visual>
        <collision>
            <origin rpy="0 0 0" xyz="0 0 0"/>
            <geometry>
                <mesh filename="meshes/gripper_v0/gripper_palm.stl"/>
            </geometry>
        </collision>
    </link>

    <link name="r_upper_arm_link">
        <inertial>
            <!-- NOTE:reflect==-1 for right side, reflect==1 for the left side -->
            <mass value="6.01769"/>
            <origin xyz="0.21398 -0.01621 -0.0002"/>
            <inertia ixx="0.01537748957" ixy="0.00375711247" ixz="-0.00070852914" iyy="0.0747367044" iyz="-0.0001793645"
                     izz="0.07608763307"/>
        </inertial>
        <visual>
            <origin rpy="0 0 0" xyz="0 0 0"/>
            <geometry>
                <mesh filename="meshes/upper_arm_v0/upper_arm.dae"/>
            </geometry>
            <material name="Green"/>
        </visual>
    </link>

    <link name="r_forearm_link">
        <inertial>
            <mass value="2.57968"/>
            <origin xyz="0.18791 -0.00017 -0.00912"/>
            <inertia ixx="0.00364857222" ixy="0.00005215877" ixz="0.00071534842" iyy="0.01507736897"
                     iyz="-0.00001310770" izz="0.01659310749"/>
        </inertial>
        <collision>
            <origin rpy="0 0 0" xyz="0 0 0"/>
            <geometry>
                <mesh filename="meshes/forearm_v0/forearm.stl"/>
            </geometry>
        </collision>
        <visual>
            <origin rpy="0 0 0" xyz="0 0 0"/>
            <geometry>
                <mesh filename="meshes/forearm_v0/forearm.dae"/>
            </geometry>
            <material name="Grey"/>
        </visual>
        <!-- TODO: collision tag should be optional -->
        <collision>
            <origin rpy="0 0 0" xyz="0 0 0"/>
            <geometry>
                <mesh filename="meshes/upper_arm_v0/forearm_roll_L.stl"/>
            </geometry>
        </collision>
    </link>


    <link name="r_elbow_flex_link">
        <inertial>
            <mass value="1.90327"/>
            <origin xyz="0.01014 0.00032 -0.01211"/>
            <inertia ixx="0.00346541989" ixy="0.00004066825" ixz="0.00043171614" iyy="0.00441606455"
                     iyz="-0.00003968914" izz="0.00359156824"/>
        </inertial>
        <visual>
            <origin rpy="0 0 0" xyz="0 0 0"/>
            <geometry>
                <mesh filename="meshes/upper_arm_v0/elbow_flex.dae"/>
            </geometry>
            <material name="first sphere"/>
        </visual>
        <visual>
            <origin xyz="0 0 0" rpy="0 0 0"/>
            <geometry>
                <sphere radius="0.105000"/>
            </geometry>
        </visual>
        <collision>
            <origin rpy="0 0 0" xyz="0 0 0"/>
            <geometry>
                <mesh filename="meshes/upper_arm_v0/elbow_flex.stl"/>
            </geometry>
        </collision>
    </link>

    <!-- maybe this can work as base frame?-->
    <link name="torso_lift_link">
        <inertial>
            <mass value="36.248046"/>
            <origin xyz="-0.1 0 0.0885"/>
            <inertia ixx="2.771653750257" ixy="0.004284522609" ixz="-0.160418504506" iyy="2.510019507959"
                     iyz="0.029664468704" izz="0.526432355569"/>
        </inertial>
        <visual>
            <origin rpy="0 0 0" xyz="-0.0 0 -0.0"/>
            <geometry>
                <mesh filename="meshes/torso_v0/torso_lift.dae"/>
            </geometry>
            <material name="Grey2"/>
        </visual>
        <collision name="torso_lift_collision">
            <origin rpy="0 0 0" xyz="-0.0 0 -0.0"/>
            <geometry>
                <mesh filename="meshes/torso_v0/torso_lift_L.stl"/>
            </geometry>
        </collision>
    </link>

    <link name="r_shoulder_pan_link">
        <inertial>
            <mass value="25.799322"/>
            <origin rpy="0 0 0" xyz="0.0 0.0 0.0"/>
            <inertia ixx="0.866179142480" ixy="-0.06086507933" ixz="-0.12118061183" iyy="0.87421714893"
                     iyz="-0.05886609911" izz="0.27353821674"/>
        </inertial>
        <visual>
            <origin rpy="0 0 0" xyz="0 0 0"/>
            <geometry>
                <mesh filename="meshes/shoulder_v0/shoulder_pan.dae"/>
            </geometry>
            <material name="Blue"/>
        </visual>
        <visual>
            <origin rpy="0 0 0" xyz="0.09 0 0"/>
            <geometry>
                <sphere radius="0.180000"/>
            </geometry>
            <material name="green">
                <color rgba="0 1 0 1"/>
            </material>
        </visual>
        <collision>
            <origin rpy="0 0 0" xyz="0.0 0 0.0"/>
            <geometry>
                <mesh filename="meshes/shoulder_v0/shoulder_pan.stl"/>
            </geometry>
        </collision>
    </link>

    <link name="r_shoulder_lift_link">
        <inertial>
            <mass value="2.74988"/>
            <origin rpy="0 0 0" xyz="0.02195 -0.02664 -0.03127"/>
            <inertia ixx="0.02105584615" ixy="0.00496704022" ixz="-0.00194808955" iyy="0.02127223737"
                     iyz="0.00110425490" izz="0.01975753814"/>
        </inertial>
        <visual>
            <origin rpy="0 0 0" xyz="0 0 0"/>
            <geometry>
                <mesh filename="meshes/shoulder_v0/shoulder_lift.dae"/>
            </geometry>
            <material name="first sphere"/>
        </visual>
        <visual>
            <origin xyz="0.18 0 -0.015" rpy="0 0 0"/>
            <geometry>
                <sphere radius="0.110000"/>
            </geometry>
        </visual>

        <visual>
            <origin xyz="0.26 0 -0.035" rpy="0 0 0"/>
            <geometry>
                <sphere radius="0.080000"/>
            </geometry>
        </visual>

        <collision>
            <origin rpy="0 0 0" xyz="0.0 0 0.0"/>
            <geometry>
                <mesh filename="meshes/shoulder_v0/shoulder_pan.stl"/>
            </geometry>
        </collision>
    </link>

    <link name="r_upper_arm_roll_link">
        <inertial>
            <!-- dummy mass, to be removed -->
            <mass value="0.1"/>
            <origin rpy="0 0 0" xyz="0 0 0"/>
            <inertia ixx="0.01" ixy="0.00" ixz="0.00" iyy="0.01" iyz="0.00" izz="0.01"/>
        </inertial>
        <visual>
            <!-- TODO: This component doesn't actually have a mesh -->
            <origin rpy="0 0 0" xyz="0 0 0"/>
            <geometry>
                <mesh filename="meshes/shoulder_v0/upper_arm_roll.stl"/>
            </geometry>
            <material name="green"/>
        </visual>

        <visual>
            <origin xyz="0.3275 0 -0.035" rpy="0 0 0"/>
            <geometry>
                <sphere radius="0.080000"/>
            </geometry>
        </visual>

        <collision>
            <origin rpy="0 0 0" xyz="0.0 0 0.0"/>
            <geometry>
                <mesh filename="meshes/shoulder_v0/shoulder_pan.stl"/>
            </geometry>
        </collision>
    </link>

    <link name="r_forearm_roll_link">
        <inertial>
            <!-- dummy masses, to be removed -->
            <mass value="0.1"/>
            <origin xyz="0 0 0"/>
            <inertia ixx="0.01" ixy="0.00" ixz="0.00" iyy="0.01" iyz="0.00" izz="0.01"/>
        </inertial>
        <visual>
            <origin rpy="0 0 0" xyz="0 0 0"/>
            <geometry>
                <mesh filename="meshes/upper_arm_v0/forearm_roll.stl"/>
            </geometry>
            <material name="green"/>
        </visual>
        <visual name="some sphere">
            <origin xyz="0.13 0 0.005" rpy="0 0 0"/>
            <geometry>
                <sphere radius="0.075000"/>
            </geometry>
        </visual>
        <visual>
            <origin xyz="0.200 0.025 -0.01" rpy="0 0 0"/>
            <geometry>
                <sphere radius="0.055000"/>
            </geometry>
        </visual>

        <visual>
            <origin xyz="0.2 -0.025 -0.01" rpy="0 0 0"/>
            <geometry>
                <sphere radius="0.055000"/>
            </geometry>
        </visual>

        <visual>
            <origin xyz="0.265 0.0275 -0.015" rpy="0 0 0"/>
            <geometry>
                <sphere radius="0.050000"/>
            </geometry>
        </visual>

        <visual>
            <origin xyz="0.265 -0.0275 -0.015" rpy="0 0 0"/>
            <geometry>
                <sphere radius="0.050000"/>
            </geometry>
        </visual>

        <visual>
            <origin xyz="0.32 0.0225 -0.005" rpy="0 0 0"/>
            <geometry>
                <sphere radius="0.050000"/>
            </geometry>
        </visual>

        <visual>
            <origin xyz="0.32 -0.0225 -0.005" rpy="0 0 0"/>
            <geometry>
                <sphere radius="0.050000"/>
            </geometry>
        </visual>
        <collision>
            <origin rpy="0 0 0" xyz="0.0 0 0.0"/>
            <geometry>
                <mesh filename="meshes/shoulder_v0/shoulder_pan.stl"/>
            </geometry>
        </collision>
    </link>

    <link name="r_wrist_roll_link">
        <inertial>
            <mass value="0.1"/>
            <origin rpy="0 0 0" xyz="0.0 0.0 0.0"/>
            <inertia ixx="0.01" ixy="0" ixz="0" iyy="0.01" iyz="0" izz="0.01"/>
        </inertial>
        <visual>
            <origin rpy="0 0 0" xyz="0 0 0"/>
            <geometry>
                <mesh filename="meshes/forearm_v0/wrist_roll.stl"/>
            </geometry>
            <material name="green"/>
        </visual>

        <visual>
            <origin xyz="0.0925 0 0" rpy="0 0 0"/>
            <geometry>
                <sphere radius="0.040000"/>
            </geometry>
        </visual>

        <!-- changes -->
        <!-- left finger spheres -->
        <visual>
            <origin xyz="0.1055 0.0350 -0.001" rpy="0 0 0"/>
            <!-- 0   -0.0360    0.1100 -->
            <!-- 0.03 0.025 0 -->
            <geometry>
                <sphere radius="0.040000"/>
            </geometry>
            <material name="first sphere">
                <color rgba="0 1 1 1"/>
            </material>
        </visual>
        <visual>
            <!-- 0.03598 0.01730  -->
            <origin xyz="0.1500 0.044 -0.001" rpy="0 0 0"/>
            <geometry>
                <sphere radius="0.035000"/>
            </geometry>
        </visual>
        <visual>
            <origin xyz="0.1800 0.0300 -0.001" rpy="0 0 0"/>
            <geometry>
                <sphere radius="0.030000"/>
            </geometry>
        </visual>
        <visual>
            <origin xyz="0.2 0.0305 0" rpy="0 0 0"/>
            <geometry>
                <sphere radius="0.020000"/>
            </geometry>
        </visual>

        <!-- right fingers -->
        <visual>
            <origin xyz="0.1055 -0.0350 -0.001" rpy="0 0 0"/>
            <!-- 0   -0.0360    0.1100 -->
            <!-- 0.03 0.025 0 -->
            <geometry>
                <sphere radius="0.040000"/>
            </geometry>
            <material name="first sphere">
                <color rgba="0 1 1 1"/>
            </material>
        </visual>
        <visual>
            <!-- 0.03598 0.01730  -->
            <origin xyz="0.1500 -0.044 -0.001" rpy="0 0 0"/>
            <geometry>
                <sphere radius="0.035000"/>
            </geometry>
        </visual>
        <visual>
            <origin xyz="0.1800 -0.0300 -0.001" rpy="0 0 0"/>
            <geometry>
                <sphere radius="0.030000"/>
            </geometry>
        </visual>
        <visual>
            <origin xyz="0.2 -0.0305 0" rpy="0 0 0"/>
            <geometry>
                <sphere radius="0.020000"/>
            </geometry>
        </visual>
        <collision>
            <origin rpy="0 0 0" xyz="0 0 0"/>
            <geometry>
                <mesh filename="meshes/forearm_v0/wrist_roll_L.stl"/>
            </geometry>
        </collision>
    </link>


    <link name="r_wrist_flex_link">
        <inertial>
            <mass value="0.61402"/>
            <origin xyz="-0.00157 0.0 -0.00075"/>
            <inertia ixx="0.00065165722" ixy="0.00000028864" ixz="0.00000303477" iyy="0.00019824443"
                     iyz="-0.00000022645" izz="0.00064450498"/>
        </inertial>
        <visual>
            <origin rpy="0 0 0" xyz="0 0 0"/>
            <geometry>
                <mesh filename="meshes/forearm_v0/wrist_flex.dae"/>
            </geometry>
            <material name="wrist">
                <color rgba="1 0 0 1"/>
            </material>
        </visual>
        <visual>
            <origin xyz="0.0725 -0.0175 0" rpy="0 0 0"/>
            <geometry>
                <sphere radius="0.040000"/>
            </geometry>
        </visual>

        <visual>
            <origin xyz="0.0725 0.0175 0" rpy="0 0 0"/>
            <geometry>
                <sphere radius="0.040000"/>
            </geometry>
        </visual>
        <collision>
            <origin rpy="0 0 0" xyz="0.0 0 0.0"/>
            <geometry>
                <mesh filename="meshes/forearm_v0/wrist_flex.stl"/>
            </geometry>
        </collision>
    </link>

    <link name="r_gripper_l_finger_link">
        <inertial>
            <mass value="0.17126"/>
            <origin rpy="0 0 0" xyz="0.03598 0.01730 -0.00164"/>
            <inertia ixx="0.00007756198" ixy="0.00000149095" ixz="-0.00000983385" iyy="0.00019708305"
                     iyz="-0.00000306125" izz="0.00018105446"/>
        </inertial>
        <visual>
            <origin rpy="0 0 0" xyz="0 0 0"/>
            <geometry>
                <mesh filename="meshes/gripper_v0/l_finger.dae"/>
            </geometry>
            <material name="Grey"/>
        </visual>
        <collision>
            <origin rpy="0 0 0" xyz="0 0 0"/>
            <geometry>
                <mesh filename="meshes/gripper_v0/l_finger.stl"/>
            </geometry>
        </collision>
    </link>

    <link name="r_gripper_l_finger_tip_link">
        <inertial>
            <mass value="0.04419"/>
            <origin rpy="0 0 0" xyz="0.00423 0.00284 0.0"/>
            <inertia ixx="0.00000837047" ixy="0.00000583632" ixz="0.0" iyy="0.00000987067" iyz="0.0"
                     izz="0.00001541768"/>
        </inertial>
        <visual>
            <origin rpy="0 0 0" xyz="0 0 0"/>
            <geometry>
                <mesh filename="meshes/gripper_v0/l_finger_tip.dae"/>
            </geometry>
            <material name="Green"/>
        </visual>

        <collision>
            <origin rpy="0 0 0" xyz="0.0 0 0.0"/>
            <geometry>
                <mesh filename="meshes/gripper_v0/l_finger_tip.stl"/>
            </geometry>
        </collision>
    </link>

    <link name="r_gripper_r_finger_link">
        <inertial>
            <mass value="0.17389"/>
            <origin rpy="0 0 0" xyz="0.03576 -0.01736 -0.00095"/>
            <inertia ixx="0.00007738410" ixy="-0.00000209309" ixz="-0.00000836228" iyy="0.00019847383"
                     iyz="0.00000246110" izz="0.00018106988"/>
        </inertial>
        <visual>
            <origin rpy="3.14159265359 0 0" xyz="0 0 0"/>
            <geometry>
                <mesh filename="meshes/gripper_v0/l_finger.dae"/>
            </geometry>
            <material name="Grey"/>
        </visual>
        <collision>
            <origin rpy="0 0 0" xyz="0.0 0 0.0"/>
            <geometry>
                <mesh filename="meshes/gripper_v0/l_finger.stl"/>
            </geometry>
        </collision>
    </link>

    <link name="r_gripper_r_finger_tip_link">
        <inertial>
            <mass value="0.04419"/>
            <origin rpy="0 0 0" xyz="0.00423 -0.00284 0.0"/>
            <inertia ixx="0.00000837047" ixy="-0.00000583632" ixz="0.0" iyy="0.00000987067" iyz="0.0"
                     izz="0.00001541768"/>
        </inertial>
        <visual>
            <origin rpy="3.14159265359 0 0" xyz="0 0 0"/>
            <geometry>
                <mesh filename="meshes/gripper_v0/l_finger_tip.dae"/>
            </geometry>
            <material name="Green"/>
        </visual>
        <collision>
            <origin rpy="0 0 0" xyz="0.0 0 0.0"/>
            <geometry>
                <mesh filename="meshes/gripper_v0/l_finger_tip.stl"/>
            </geometry>
        </collision>
    </link>
</robot>