<?xml version="1.0" ?>
<!-- =================================================================================== -->
<!-- |    This document was autogenerated by xacro from urdf/iiwa7.urdf.xacro          | -->
<!-- |    EDITING THIS FILE BY HAND IS NOT RECOMMENDED                                 | -->
<!-- =================================================================================== -->
<!--|
    Copyright (C) 2019-2022 Learning Algorithms and Systems Laboratory, EPFL, Switzerland
    Authors:  Konstantinos Chatzilygeroudis (maintainer)
              Matthias Mayr
              Bernardo Fichera
    email:    costashatz@gmail.com
              matthias.mayr@cs.lth.se
              bernardo.fichera@epfl.ch
    Other contributors:
              Yoan Mollard (yoan@aubrune.eu)
              Walid Amanhoud (walid.amanhoud@epfl.ch)
    website:  lasa.epfl.ch

    This file is part of iiwa_ros.

    iiwa_ros is free software: you can redistribute it and/or modify
    it under the terms of the GNU General Public License as published by
    the Free Software Foundation, either version 3 of the License, or
    (at your option) any later version.

    iiwa_ros is distributed in the hope that it will be useful,
    but WITHOUT ANY WARRANTY; without even the implied warranty of
    MERCHANTABILITY or FITNESS FOR A PARTICULAR PURPOSE.  See the
    GNU General Public License for more details.

|-->
<robot xmlns:xacro="http://www.ros.org/wiki/xacro" name="iiwa7">
  <!-- Import Rviz colors -->
  <material name="Black">
    <color rgba="0.0 0.0 0.0 1.0"/>
  </material>
  <material name="Blue">
    <color rgba="0.0 0.0 0.8 1.0"/>
  </material>
  <material name="Green">
    <color rgba="0.0 0.8 0.0 1.0"/>
  </material>
  <material name="Grey">
    <color rgba="0.4 0.4 0.4 1.0"/>
  </material>
  <material name="Orange">
    <color rgba="1.0 0.4235294117647059 0.0392156862745098 1.0"/>
  </material>
  <material name="Brown">
    <color rgba="0.8705882352941177 0.8117647058823529 0.7647058823529411 1.0"/>
  </material>
  <material name="Red">
    <color rgba="0.8 0.0 0.0 1.0"/>
  </material>
  <material name="White">
    <color rgba="1.0 1.0 1.0 1.0"/>
  </material>
  <material name="Transparent">
    <color rgba="1.0 1.0 0.0 0.0"/>
  </material>

  <!-- Fix to world just for testing -->
  <link name="world"/>
  <!--iiwa-->
  <joint name="iiwa_description_joint" type="fixed">
    <origin xyz="0 0 0" rpy="0 0 0"/>
    <parent link="world"/>
    <child link="iiwa_description_link_0"/>
  </joint>
  <link name="iiwa_description_link_0">
    <inertial>
      <origin xyz="-0.1 0 0.07" rpy="0 0 0"/>
      <mass value="5"/>
      <inertia ixx="0.05" ixy="0" ixz="0" iyy="0.06" iyz="0" izz="0.03"/>
    </inertial>
    <visual>
      <origin xyz="0 0 0" rpy="0 0 0"/>
      <geometry>
        <mesh filename="package://meshes/iiwa7/visual/link_0.stl"/>
      </geometry>
      <material name="Grey"/>
    </visual>
    <collision>
      <origin xyz="0 0 0" rpy="0 0 0"/>
      <geometry>
        <mesh filename="package://meshes/iiwa7/collision/link_0.stl"/>
      </geometry>
      <material name="Grey"/>
    </collision>
    <visual name="ball_0">
      <origin xyz="0.0 0.0 0.0" rpy="0.0 0.0 0.0"/>
      <geometry>
        <sphere radius="0.14"/>
      </geometry>
      <material name="Grey"/>
    </visual>
    <visual name="ball_0">
      <origin xyz="-0.05 0.0 0.05" rpy="0.0 0.0 0.0"/>
      <geometry>
        <sphere radius="0.14"/>
      </geometry>
      <material name="Grey"/>
    </visual>
  </link>
  <joint name="iiwa_description_joint_1" type="revolute">
    <parent link="iiwa_description_link_0"/>
    <child link="iiwa_description_link_1"/>
    <origin xyz="0 0 0.15" rpy="0 0 0"/>
    <axis xyz="0 0 1"/>
    <limit lower="-2.9670597283903604" upper="2.9670597283903604" effort="176" velocity="1.710422666954443"/>
    <xacro:if value="true">
      <safety_controller soft_lower_limit="-2.8187067419708423" soft_upper_limit="2.8187067419708423" k_position="100" k_velocity="10"/>
    </xacro:if>
    <dynamics damping="0.5"/>
  </joint>
  <link name="iiwa_description_link_1">
    <inertial>
      <origin xyz="0 -0.03 0.12" rpy="0 0 0"/>
      <mass value="3.4525"/>
      <inertia ixx="0.02183" ixy="0" ixz="0" iyy="0.007703" iyz="-0.003887" izz="0.02083"/>
    </inertial>
    <visual>
      <origin xyz="0 0 0.0075" rpy="0 0 0"/>
      <geometry>
        <mesh filename="package://meshes/iiwa7/visual/link_1.stl"/>
      </geometry>
      <material name="Orange"/>
    </visual>
    <collision>
      <origin xyz="0 0 0.0075" rpy="0 0 0"/>
      <geometry>
        <mesh filename="package://meshes/iiwa7/collision/link_1.stl"/>
      </geometry>
      <material name="Orange"/>
    </collision>

    <visual name="ball_0">
      <origin xyz="0.0 0.0 0.0" rpy="0.0 0.0 0.0"/>
      <geometry>
        <sphere radius="0.09"/>
      </geometry>
      <material name="Orange"/>
    </visual>
    <visual name="ball_0">
      <origin xyz="0.0 -0.04 0.1" rpy="0.0 0.0 0.0"/>
      <geometry>
        <sphere radius="0.09"/>
      </geometry>
      <material name="orange"/>
    </visual>
    <visual name="ball_0">
      <origin xyz="0.0 -0.07 0.18" rpy="0.0 0.0 0.0"/>
      <geometry>
        <sphere radius="0.09"/>
      </geometry>
      <material name="Orange"/>
    </visual>
  </link>
  <joint name="iiwa_description_joint_2" type="revolute">
    <parent link="iiwa_description_link_1"/>
    <child link="iiwa_description_link_2"/>
    <origin xyz="0 0 0.19" rpy="1.5707963267948966   0 3.141592653589793"/>
    <axis xyz="0 0 1"/>
    <limit lower="-2.0943951023931953" upper="2.0943951023931953" effort="176" velocity="1.710422666954443"/>
    <xacro:if value="true">
      <safety_controller soft_lower_limit="-1.9896753472735356" soft_upper_limit="1.9896753472735356" k_position="100" k_velocity="10"/>
    </xacro:if>
    <dynamics damping="0.5"/>
  </joint>
  <link name="iiwa_description_link_2">
    <inertial>
      <origin xyz="0.0003 0.059 0.042" rpy="0 0 0"/>
      <mass value="3.4821"/>
      <inertia ixx="0.02076" ixy="0" ixz="-0.003626" iyy="0.02179" iyz="0" izz="0.00779"/>
    </inertial>
    <visual>
      <origin xyz="0 0 0" rpy="0 0 0"/>
      <geometry>
        <mesh filename="package://meshes/iiwa7/visual/link_2.stl"/>
      </geometry>
      <material name="Orange"/>
    </visual>
    <collision>
      <origin xyz="0 0 0" rpy="0 0 0"/>
      <geometry>
        <mesh filename="package://meshes/iiwa7/collision/link_2.stl"/>
      </geometry>
      <material name="Orange"/>
    </collision>

    <visual name="ball_0">
      <origin xyz="0.0 0.0 0.0" rpy="0.0 0.0 0.0"/>
      <geometry>
        <sphere radius="0.09"/>
      </geometry>
      <material name="Orange"/>
    </visual>
    <visual name="ball_0">
      <origin xyz="0.0 0.0 0.06" rpy="0.0 0.0 0.0"/>
      <geometry>
        <sphere radius="0.09"/>
      </geometry>
      <material name="Orange"/>
    </visual>
    <visual name="ball_0">
      <origin xyz="0.0 0.1 0.011" rpy="0.0 0.0 0.0"/>
      <geometry>
        <sphere radius="0.11"/>
      </geometry>
      <material name="Orange"/>
    </visual>
  </link>
  <joint name="iiwa_description_joint_3" type="revolute">
    <parent link="iiwa_description_link_2"/>
    <child link="iiwa_description_link_3"/>
    <origin xyz="0 0.21 0" rpy="1.5707963267948966 0 3.141592653589793"/>
    <axis xyz="0 0 1"/>
    <limit lower="-2.9670597283903604" upper="2.9670597283903604" effort="110" velocity="1.7453292519943295"/>
    <xacro:if value="true">
      <safety_controller soft_lower_limit="-2.8187067419708423" soft_upper_limit="2.8187067419708423" k_position="100" k_velocity="10"/>
    </xacro:if>
    <dynamics damping="0.5"/>
  </joint>
  <link name="iiwa_description_link_3">
    <inertial>
      <origin xyz="0 0.03 0.13" rpy="0 0 0"/>
      <mass value="4.05623"/>
      <inertia ixx="0.03204" ixy="0" ixz="0" iyy="0.00972" iyz="0.006227" izz="0.03042"/>
    </inertial>
    <visual>
      <origin xyz="0 0 -0.026" rpy="0 0 0"/>
      <geometry>
        <mesh filename="package://meshes/iiwa7/visual/link_3.stl"/>
      </geometry>
      <material name="Orange"/>
    </visual>
    <collision>
      <origin xyz="0 0 -0.026" rpy="0 0 0"/>
      <geometry>
        <mesh filename="package://meshes/iiwa7/collision/link_3.stl"/>
      </geometry>
      <material name="Orange"/>
    </collision>

    <visual name="ball_0">
      <origin xyz="0.0 0.0 0.0" rpy="0.0 0.0 0.0"/>
      <geometry>
        <sphere radius="0.09"/>
      </geometry>
      <material name="Orange"/>
    </visual>
    <visual name="ball_0">
      <origin xyz="0.0 0.055 0.1" rpy="0.0 0.0 0.0"/>
      <geometry>
        <sphere radius="0.09"/>
      </geometry>
      <material name="Orange"/>
    </visual>
    <visual name="ball_0">
      <origin xyz="0.0 0.06 0.18" rpy="0.0 0.0 0.0"/>
      <geometry>
        <sphere radius="0.09"/>
      </geometry>
      <material name="Orange"/>
    </visual>
  </link>
  <joint name="iiwa_description_joint_4" type="revolute">
    <parent link="iiwa_description_link_3"/>
    <child link="iiwa_description_link_4"/>
    <origin xyz="0 0 0.19" rpy="1.5707963267948966 0 0"/>
    <axis xyz="0 0 1"/>
    <limit lower="-2.0943951023931953" upper="2.0943951023931953" effort="110" velocity="2.2689280275926285"/>
    <xacro:if value="true">
      <safety_controller soft_lower_limit="-1.9896753472735356" soft_upper_limit="1.9896753472735356" k_position="100" k_velocity="10"/>
    </xacro:if>
    <dynamics damping="0.5"/>
  </joint>
  <link name="iiwa_description_link_4">
    <inertial>
      <origin xyz="0 0.067 0.034" rpy="0 0 0"/>
      <mass value="3.4822"/>
      <inertia ixx="0.02178" ixy="0" ixz="0" iyy="0.02075" iyz="-0.003625" izz="0.007785"/>
    </inertial>
    <visual>
      <origin xyz="0 0 0" rpy="0 0 0"/>
      <geometry>
        <mesh filename="package://meshes/iiwa7/visual/link_4.stl"/>
      </geometry>
      <material name="Orange"/>
    </visual>
    <collision>
      <origin xyz="0 0 0" rpy="0 0 0"/>
      <geometry>
        <mesh filename="package://meshes/iiwa7/collision/link_4.stl"/>
      </geometry>
      <material name="Orange"/>
    </collision>

    <visual name="ball_0">
      <origin xyz="0.0 0.0 0.0" rpy="0.0 0.0 0.0"/>
      <geometry>
        <sphere radius="0.08"/>
      </geometry>
      <material name="Orange"/>
    </visual>
    <visual name="ball_0">
      <origin xyz="0.0 0.15 0.0" rpy="0.0 0.0 0.0"/>
      <geometry>
        <sphere radius="0.08"/>
      </geometry>
      <material name="Orange"/>
    </visual>
    <visual name="ball_0">
      <origin xyz="0.0 0.01 0.05" rpy="0.0 0.0 0.0"/>
      <geometry>
        <sphere radius="0.08"/>
      </geometry>
      <material name="Orange"/>
    </visual>
    <visual name="ball_0">
      <origin xyz="0.0 0.09 0.05" rpy="0.0 0.0 0.0"/>
      <geometry>
        <sphere radius="0.08"/>
      </geometry>
      <material name="Orange"/>
    </visual>
  </link>
  <joint name="iiwa_description_joint_5" type="revolute">
    <parent link="iiwa_description_link_4"/>
    <child link="iiwa_description_link_5"/>
    <origin xyz="0 0.21 0" rpy="-1.5707963267948966 3.141592653589793 0"/>
    <axis xyz="0 0 1"/>
    <limit lower="-2.9670597283903604" upper="2.9670597283903604" effort="110" velocity="2.443460952792061"/>
    <xacro:if value="true">
      <safety_controller soft_lower_limit="-2.8187067419708423" soft_upper_limit="2.8187067419708423" k_position="100" k_velocity="10"/>
    </xacro:if>
    <dynamics damping="0.5"/>
  </joint>
  <link name="iiwa_description_link_5">
    <inertial>
      <origin xyz="0.0001 0.021 0.076" rpy="0 0 0"/>
      <mass value="2.1633"/>
      <inertia ixx="0.01287" ixy="0" ixz="0" iyy="0.005708" iyz="-0.003946" izz="0.01112"/>
    </inertial>
    <visual>
      <origin xyz="0 0 -0.026" rpy="0 0 0"/>
      <geometry>
        <mesh filename="package://meshes/iiwa7/visual/link_5.stl"/>
      </geometry>
      <material name="Orange"/>
    </visual>
    <collision>
      <origin xyz="0 0 -0.026" rpy="0 0 0"/>
      <geometry>
        <mesh filename="package://meshes/iiwa7/collision/link_5.stl"/>
      </geometry>
      <material name="Orange"/>
    </collision>

    <visual name="ball_0">
      <origin xyz="0.0 0.0 0.0" rpy="0.0 0.0 0.0"/>
      <geometry>
        <sphere radius="0.085"/>
      </geometry>
      <material name="Orange"/>
    </visual>
    <visual name="ball_0">
      <origin xyz="0.0 0.06 0.1" rpy="0.0 0.0 0.0"/>
      <geometry>
        <sphere radius="0.085"/>
      </geometry>
      <material name="Orange"/>
    </visual>
  </link>
  <joint name="iiwa_description_joint_6" type="revolute">
    <parent link="iiwa_description_link_5"/>
    <child link="iiwa_description_link_6"/>
    <origin xyz="0 0.06070 0.19" rpy="1.5707963267948966 0 0"/>
    <axis xyz="0 0 1"/>
    <limit lower="-2.0943951023931953" upper="2.0943951023931953" effort="40" velocity="3.141592653589793"/>
    <xacro:if value="true">
      <safety_controller soft_lower_limit="-1.9896753472735356" soft_upper_limit="1.9896753472735356" k_position="100" k_velocity="10"/>
    </xacro:if>
    <dynamics damping="0.5"/>
  </joint>
  <link name="iiwa_description_link_6">
    <inertial>
      <origin xyz="0 0.0006 0.0004" rpy="0 0 0"/>
      <mass value="2.3466"/>
      <inertia ixx="0.006509" ixy="0" ixz="0" iyy="0.006259" iyz="0.00031891" izz="0.004527"/>
    </inertial>
    <visual>
      <origin xyz="0 0 0" rpy="0 0 0"/>
      <geometry>
        <mesh filename="package://meshes/iiwa7/visual/link_6.stl"/>
      </geometry>
      <material name="Orange"/>
    </visual>
    <collision>
      <origin xyz="0 0 0" rpy="0 0 0"/>
      <geometry>
        <mesh filename="package://meshes/iiwa7/collision/link_6.stl"/>
      </geometry>
      <material name="Orange"/>
    </collision>
    
    <visual name="ball_0">
      <origin xyz="0.0 0.0 0.0" rpy="0.0 0.0 0.0"/>
      <geometry>
        <sphere radius="0.08"/>
      </geometry>
      <material name="Orange"/>
    </visual>
    <visual name="ball_0">
      <origin xyz="0.0 0.03 0.07" rpy="0.0 0.0 0.0"/>
      <geometry>
        <sphere radius="0.08"/>
      </geometry>
      <material name="Orange"/>
    </visual>
    <visual name="ball_0">
      <origin xyz="0.0 -0.03 0.07" rpy="0.0 0.0 0.0"/>
      <geometry>
        <sphere radius="0.08"/>
      </geometry>
      <material name="Orange"/>
    </visual>

  </link>
  <joint name="iiwa_description_joint_7" type="revolute">
    <parent link="iiwa_description_link_6"/>
    <child link="iiwa_description_link_7"/>
    <origin xyz="0 0.081 0.06070" rpy="-1.5707963267948966 3.141592653589793 0"/>
    <axis xyz="0 0 1"/>
    <limit lower="-3.0543261909900763" upper="3.0543261909900763" effort="40" velocity="3.141592653589793"/>
    <xacro:if value="true">
      <safety_controller soft_lower_limit="-2.901609881440573" soft_upper_limit="2.901609881440573" k_position="100" k_velocity="10"/>
    </xacro:if>
    <dynamics damping="0.5"/>
  </joint>
  <link name="iiwa_description_link_7">
    <inertial>
      <origin xyz="0 0 0.02" rpy="0 0 0"/>
      <mass value="3.129"/>
      <inertia ixx="0.01464" ixy="0.0005912" ixz="0" iyy="0.01465" iyz="0" izz="0.002872"/>
    </inertial>
    <visual>
      <origin xyz="0 0 -0.0005" rpy="0 0 0"/>
      <geometry>
        <mesh filename="package://meshes/iiwa7/visual/link_7.stl"/>
      </geometry>
      <material name="Grey"/>
    </visual>
    <collision>
      <origin xyz="0 0 -0.0005" rpy="0 0 0"/>
      <geometry>
        <mesh filename="package://meshes/iiwa7/collision/link_7.stl"/>
      </geometry>
      <material name="Grey"/>
    </collision>

    <visual name="ball_0">
      <origin xyz="0.0 0.0 0.0" rpy="0.0 0.0 0.0"/>
      <geometry>
        <sphere radius="0.058"/>
      </geometry>
    </visual>
  </link>
  <joint name="iiwa_description_joint_ee" type="fixed">
    <parent link="iiwa_description_link_7"/>
    <child link="iiwa_description_link_ee"/>
    <origin xyz="0 0 0.045" rpy="0 0 0"/>
  </joint>
  <link name="iiwa_description_link_ee">
    <inertial>
      <origin xyz="0 0 0" rpy="0 0 0"/>
      <mass value="1e-6"/>
      <inertia ixx="1" ixy="0" ixz="0" iyy="1" iyz="0" izz="1"/>
    </inertial>
  </link>
  
</robot>
